<?xml version="1.0" encoding="UTF-8"?>
<!DOCTYPE html PUBLIC "-//W3C//DTD XHTML 1.0 Strict//EN" "http://www.w3.org/TR/xhtml1/DTD/xhtml1-strict.dtd">
<html xmlns="http://www.w3.org/1999/xhtml">
<head>
    <title>自动化测试报告</title>
    <meta name="generator" content="HTMLTestRunner 0.9.1"/>
    <meta http-equiv="Content-Type" content="text/html; charset=UTF-8"/>
    
    <link href="http://cdn.bootcss.com/bootstrap/3.3.0/css/bootstrap.min.css" rel="stylesheet">
    <script src="https://cdn.bootcss.com/echarts/4.1.0.rc2/echarts.common.min.js"></script>
    <!-- <script type="text/javascript" src="js/echarts.common.min.js"></script> -->
    
    
<style type="text/css" media="screen">
    body        { font-family: Microsoft YaHei,Consolas,arial,sans-serif; font-size: 80%; }
    table       { font-size: 100%; }
    pre         { white-space: pre-wrap;word-wrap: break-word; }

    /* -- heading ---------------------------------------------------------------------- */
    h1 {
        font-size: 16pt;
        color: gray;
    }
    .heading {
        margin-top: 0ex;
        margin-bottom: 1ex;
    }

    .heading .attribute {
        margin-top: 1ex;
        margin-bottom: 0;
    }

    .heading .description {
        margin-top: 2ex;
        margin-bottom: 3ex;
    }

    /* -- css div popup ------------------------------------------------------------------------ */
    a.popup_link {
    }

    a.popup_link:hover {
        color: red;
    }

    .popup_window {
        display: none;
        position: relative;
        left: 0px;
        top: 0px;
        /*border: solid #627173 1px; */
        padding: 10px;
        /*background-color: #E6E6D6; */
        font-family: "Lucida Console", "Courier New", Courier, monospace;
        text-align: left;
        font-size: 8pt;
        /* width: 500px;*/
    }

    }
    /* -- report ------------------------------------------------------------------------ */
    #show_detail_line {
        margin-top: 3ex;
        margin-bottom: 1ex;
    }
    #result_table {
        width: 99%;
    }
    #header_row {
        font-weight: bold;
        color: #303641;
        background-color: #ebebeb;
    }
    #total_row  { font-weight: bold; }
    .passClass  { background-color: #bdedbc; }
    .failClass  { background-color: #ffefa4; }
    .errorClass { background-color: #ffc9c9; }
    .passCase   { color: #6c6; }
    .failCase   { color: #FF6600; font-weight: bold; }
    .errorCase  { color: #c00; font-weight: bold; }
    .hiddenRow  { display: none; }
    .testcase   { margin-left: 2em; }


    /* -- ending ---------------------------------------------------------------------- */
    #ending {
    }

    #div_base {
                position:absolute;
                top:0%;
                left:5%;
                right:5%;
                width: auto;
                height: auto;
                margin: -15px 0 0 0;
    }
</style>

    
</head>
<body>
    <script language="javascript" type="text/javascript"><!--
    output_list = Array();

    /* level - 0:Summary; 1:Failed; 2:All */
    function showCase(level) {
        trs = document.getElementsByTagName("tr");
        for (var i = 0; i < trs.length; i++) {
            tr = trs[i];
            id = tr.id;
            if (id.substr(0,2) == 'ft') {
                if (level < 1) {
                    tr.className = 'hiddenRow';
                }
                else {
                    tr.className = '';
                }
            }
            if (id.substr(0,2) == 'pt') {
                if (level > 1) {
                    tr.className = '';
                }
                else {
                    tr.className = 'hiddenRow';
                }
            }
        }
    }


    function showClassDetail(cid, count) {
        var id_list = Array(count);
        var toHide = 1;
        for (var i = 0; i < count; i++) {
            tid0 = 't' + cid.substr(1) + '.' + (i+1);
            tid = 'f' + tid0;
            tr = document.getElementById(tid);
            if (!tr) {
                tid = 'p' + tid0;
                tr = document.getElementById(tid);
            }
            id_list[i] = tid;
            if (tr.className) {
                toHide = 0;
            }
        }
        for (var i = 0; i < count; i++) {
            tid = id_list[i];
            if (toHide) {
                document.getElementById('div_'+tid).style.display = 'none'
                document.getElementById(tid).className = 'hiddenRow';
            }
            else {
                document.getElementById(tid).className = '';
            }
        }
    }


    function showTestDetail(div_id){
        var details_div = document.getElementById(div_id)
        var displayState = details_div.style.display
        // alert(displayState)
        if (displayState != 'block' ) {
            displayState = 'block'
            details_div.style.display = 'block'
        }
        else {
            details_div.style.display = 'none'
        }
    }


    function html_escape(s) {
        s = s.replace(/&/g,'&amp;');
        s = s.replace(/</g,'&lt;');
        s = s.replace(/>/g,'&gt;');
        return s;
    }

    /* obsoleted by detail in <div>
    function showOutput(id, name) {
        var w = window.open("", //url
                        name,
                        "resizable,scrollbars,status,width=800,height=450");
        d = w.document;
        d.write("<pre>");
        d.write(html_escape(output_list[id]));
        d.write("\n");
        d.write("<a href='javascript:window.close()'>close</a>\n");
        d.write("</pre>\n");
        d.close();
    }
    */
    --></script>

    <div id="div_base">
        
    <div class='page-header'>
        <h1>自动化测试报告</h1>
    <p class='attribute'><strong>开始时间:</strong> 2019-01-08 11:42:29</p>
<p class='attribute'><strong>运行时长:</strong> 0:00:00.062000</p>
<p class='attribute'><strong>状态:</strong> 错误 42</p>

    </div>
    <div style="float: left;width:50%;"><p class='description'>运行环境：win7 Chrome</p></div>
    <div id="chart" style="width:50%;height:400px;float:left;"></div>

        
    <div class="btn-group btn-group-sm">
        <button class="btn btn-default" onclick='javascript:showCase(0)'>总结</button>
        <button class="btn btn-default" onclick='javascript:showCase(1)'>失败</button>
        <button class="btn btn-default" onclick='javascript:showCase(2)'>全部</button>
    </div>
    <p></p>
    <table id='result_table' class="table table-bordered">
        <colgroup>
            <col align='left' />
            <col align='right' />
            <col align='right' />
            <col align='right' />
            <col align='right' />
            <col align='right' />
        </colgroup>
        <tr id='header_row'>
            <td>测试套件/测试用例</td>
            <td>总数</td>
            <td>通过</td>
            <td>失败</td>
            <td>错误</td>
            <td>查看</td>
        </tr>
        
    <tr class='errorClass'>
        <td>case_goods.My_home_case</td>
        <td>36</td>
        <td>0</td>
        <td>0</td>
        <td>36</td>
        <td><a href="javascript:showClassDetail('c1',36)">详情</a></td>
    </tr>

<tr id='ft1.1' class='none'>
    <td class='errorCase'><div class='testcase'>test_autid_button: 验证审核按钮_retry:1</div></td>
    <td colspan='5' align='center'>

    <!--css div popup start-->
    <a class="popup_link" onfocus='this.blur();' href="javascript:showTestDetail('div_ft1.1')" >
        错误</a>

    <div id='div_ft1.1' class="popup_window">
        <pre>ft1.1: Traceback (most recent call last):
  File "C:\Users\pc\AppData\Local\Programs\Python\Python36\lib\site-packages\selenium\webdriver\common\service.py", line 76, in start
    stdin=PIPE)
  File "C:\Users\pc\AppData\Local\Programs\Python\Python36\lib\subprocess.py", line 709, in __init__
    restore_signals, start_new_session)
  File "C:\Users\pc\AppData\Local\Programs\Python\Python36\lib\subprocess.py", line 997, in _execute_child
    startupinfo)
FileNotFoundError: [WinError 2] 系统找不到指定的文件。

During handling of the above exception, another exception occurred:

Traceback (most recent call last):
  File "G:\Operating_background_test_01\test_case\mytest.py", line 18, in setUp
    self.driver=d.browser_chrome()
  File "G:\Operating_background_test_01\modle\driver.py", line 23, in browser_chrome
    self.driver=webdriver.Chrome(executable_path=os.path.abspath('..')+'\\Application60\\chromedriver.exe')
  File "C:\Users\pc\AppData\Local\Programs\Python\Python36\lib\site-packages\selenium\webdriver\chrome\webdriver.py", line 73, in __init__
    self.service.start()
  File "C:\Users\pc\AppData\Local\Programs\Python\Python36\lib\site-packages\selenium\webdriver\common\service.py", line 83, in start
    os.path.basename(self.path), self.start_error_message)
selenium.common.exceptions.WebDriverException: Message: 'chromedriver.exe' executable needs to be in PATH. Please see https://sites.google.com/a/chromium.org/chromedriver/home

</pre>
    </div>
    <!--css div popup end-->

    </td>
</tr>

<tr id='ft1.2' class='none'>
    <td class='errorCase'><div class='testcase'>test_click_class: 验证添加商品_retry:1</div></td>
    <td colspan='5' align='center'>

    <!--css div popup start-->
    <a class="popup_link" onfocus='this.blur();' href="javascript:showTestDetail('div_ft1.2')" >
        错误</a>

    <div id='div_ft1.2' class="popup_window">
        <pre>ft1.2: Traceback (most recent call last):
  File "C:\Users\pc\AppData\Local\Programs\Python\Python36\lib\site-packages\selenium\webdriver\common\service.py", line 76, in start
    stdin=PIPE)
  File "C:\Users\pc\AppData\Local\Programs\Python\Python36\lib\subprocess.py", line 709, in __init__
    restore_signals, start_new_session)
  File "C:\Users\pc\AppData\Local\Programs\Python\Python36\lib\subprocess.py", line 997, in _execute_child
    startupinfo)
FileNotFoundError: [WinError 2] 系统找不到指定的文件。

During handling of the above exception, another exception occurred:

Traceback (most recent call last):
  File "G:\Operating_background_test_01\test_case\mytest.py", line 18, in setUp
    self.driver=d.browser_chrome()
  File "G:\Operating_background_test_01\modle\driver.py", line 23, in browser_chrome
    self.driver=webdriver.Chrome(executable_path=os.path.abspath('..')+'\\Application60\\chromedriver.exe')
  File "C:\Users\pc\AppData\Local\Programs\Python\Python36\lib\site-packages\selenium\webdriver\chrome\webdriver.py", line 73, in __init__
    self.service.start()
  File "C:\Users\pc\AppData\Local\Programs\Python\Python36\lib\site-packages\selenium\webdriver\common\service.py", line 83, in start
    os.path.basename(self.path), self.start_error_message)
selenium.common.exceptions.WebDriverException: Message: 'chromedriver.exe' executable needs to be in PATH. Please see https://sites.google.com/a/chromium.org/chromedriver/home

</pre>
    </div>
    <!--css div popup end-->

    </td>
</tr>

<tr id='ft1.3' class='none'>
    <td class='errorCase'><div class='testcase'>test_delete_page_break: 商品回收站页面，验证切换分页下拉框_retry:1</div></td>
    <td colspan='5' align='center'>

    <!--css div popup start-->
    <a class="popup_link" onfocus='this.blur();' href="javascript:showTestDetail('div_ft1.3')" >
        错误</a>

    <div id='div_ft1.3' class="popup_window">
        <pre>ft1.3: Traceback (most recent call last):
  File "C:\Users\pc\AppData\Local\Programs\Python\Python36\lib\site-packages\selenium\webdriver\common\service.py", line 76, in start
    stdin=PIPE)
  File "C:\Users\pc\AppData\Local\Programs\Python\Python36\lib\subprocess.py", line 709, in __init__
    restore_signals, start_new_session)
  File "C:\Users\pc\AppData\Local\Programs\Python\Python36\lib\subprocess.py", line 997, in _execute_child
    startupinfo)
FileNotFoundError: [WinError 2] 系统找不到指定的文件。

During handling of the above exception, another exception occurred:

Traceback (most recent call last):
  File "G:\Operating_background_test_01\test_case\mytest.py", line 18, in setUp
    self.driver=d.browser_chrome()
  File "G:\Operating_background_test_01\modle\driver.py", line 23, in browser_chrome
    self.driver=webdriver.Chrome(executable_path=os.path.abspath('..')+'\\Application60\\chromedriver.exe')
  File "C:\Users\pc\AppData\Local\Programs\Python\Python36\lib\site-packages\selenium\webdriver\chrome\webdriver.py", line 73, in __init__
    self.service.start()
  File "C:\Users\pc\AppData\Local\Programs\Python\Python36\lib\site-packages\selenium\webdriver\common\service.py", line 83, in start
    os.path.basename(self.path), self.start_error_message)
selenium.common.exceptions.WebDriverException: Message: 'chromedriver.exe' executable needs to be in PATH. Please see https://sites.google.com/a/chromium.org/chromedriver/home

</pre>
    </div>
    <!--css div popup end-->

    </td>
</tr>

<tr id='ft1.4' class='none'>
    <td class='errorCase'><div class='testcase'>test_delete_shop: 验证删除上架商品_retry:1</div></td>
    <td colspan='5' align='center'>

    <!--css div popup start-->
    <a class="popup_link" onfocus='this.blur();' href="javascript:showTestDetail('div_ft1.4')" >
        错误</a>

    <div id='div_ft1.4' class="popup_window">
        <pre>ft1.4: Traceback (most recent call last):
  File "C:\Users\pc\AppData\Local\Programs\Python\Python36\lib\site-packages\selenium\webdriver\common\service.py", line 76, in start
    stdin=PIPE)
  File "C:\Users\pc\AppData\Local\Programs\Python\Python36\lib\subprocess.py", line 709, in __init__
    restore_signals, start_new_session)
  File "C:\Users\pc\AppData\Local\Programs\Python\Python36\lib\subprocess.py", line 997, in _execute_child
    startupinfo)
FileNotFoundError: [WinError 2] 系统找不到指定的文件。

During handling of the above exception, another exception occurred:

Traceback (most recent call last):
  File "G:\Operating_background_test_01\test_case\mytest.py", line 18, in setUp
    self.driver=d.browser_chrome()
  File "G:\Operating_background_test_01\modle\driver.py", line 23, in browser_chrome
    self.driver=webdriver.Chrome(executable_path=os.path.abspath('..')+'\\Application60\\chromedriver.exe')
  File "C:\Users\pc\AppData\Local\Programs\Python\Python36\lib\site-packages\selenium\webdriver\chrome\webdriver.py", line 73, in __init__
    self.service.start()
  File "C:\Users\pc\AppData\Local\Programs\Python\Python36\lib\site-packages\selenium\webdriver\common\service.py", line 83, in start
    os.path.basename(self.path), self.start_error_message)
selenium.common.exceptions.WebDriverException: Message: 'chromedriver.exe' executable needs to be in PATH. Please see https://sites.google.com/a/chromium.org/chromedriver/home

</pre>
    </div>
    <!--css div popup end-->

    </td>
</tr>

<tr id='ft1.5' class='none'>
    <td class='errorCase'><div class='testcase'>test_delete_shop01: 验证删除下架商品_retry:1</div></td>
    <td colspan='5' align='center'>

    <!--css div popup start-->
    <a class="popup_link" onfocus='this.blur();' href="javascript:showTestDetail('div_ft1.5')" >
        错误</a>

    <div id='div_ft1.5' class="popup_window">
        <pre>ft1.5: Traceback (most recent call last):
  File "C:\Users\pc\AppData\Local\Programs\Python\Python36\lib\site-packages\selenium\webdriver\common\service.py", line 76, in start
    stdin=PIPE)
  File "C:\Users\pc\AppData\Local\Programs\Python\Python36\lib\subprocess.py", line 709, in __init__
    restore_signals, start_new_session)
  File "C:\Users\pc\AppData\Local\Programs\Python\Python36\lib\subprocess.py", line 997, in _execute_child
    startupinfo)
FileNotFoundError: [WinError 2] 系统找不到指定的文件。

During handling of the above exception, another exception occurred:

Traceback (most recent call last):
  File "G:\Operating_background_test_01\test_case\mytest.py", line 18, in setUp
    self.driver=d.browser_chrome()
  File "G:\Operating_background_test_01\modle\driver.py", line 23, in browser_chrome
    self.driver=webdriver.Chrome(executable_path=os.path.abspath('..')+'\\Application60\\chromedriver.exe')
  File "C:\Users\pc\AppData\Local\Programs\Python\Python36\lib\site-packages\selenium\webdriver\chrome\webdriver.py", line 73, in __init__
    self.service.start()
  File "C:\Users\pc\AppData\Local\Programs\Python\Python36\lib\site-packages\selenium\webdriver\common\service.py", line 83, in start
    os.path.basename(self.path), self.start_error_message)
selenium.common.exceptions.WebDriverException: Message: 'chromedriver.exe' executable needs to be in PATH. Please see https://sites.google.com/a/chromium.org/chromedriver/home

</pre>
    </div>
    <!--css div popup end-->

    </td>
</tr>

<tr id='ft1.6' class='none'>
    <td class='errorCase'><div class='testcase'>test_delete_shop_class_and_name: 商品回收站，以商品分类和商家名称查询_retry:1</div></td>
    <td colspan='5' align='center'>

    <!--css div popup start-->
    <a class="popup_link" onfocus='this.blur();' href="javascript:showTestDetail('div_ft1.6')" >
        错误</a>

    <div id='div_ft1.6' class="popup_window">
        <pre>ft1.6: Traceback (most recent call last):
  File "C:\Users\pc\AppData\Local\Programs\Python\Python36\lib\site-packages\selenium\webdriver\common\service.py", line 76, in start
    stdin=PIPE)
  File "C:\Users\pc\AppData\Local\Programs\Python\Python36\lib\subprocess.py", line 709, in __init__
    restore_signals, start_new_session)
  File "C:\Users\pc\AppData\Local\Programs\Python\Python36\lib\subprocess.py", line 997, in _execute_child
    startupinfo)
FileNotFoundError: [WinError 2] 系统找不到指定的文件。

During handling of the above exception, another exception occurred:

Traceback (most recent call last):
  File "G:\Operating_background_test_01\test_case\mytest.py", line 18, in setUp
    self.driver=d.browser_chrome()
  File "G:\Operating_background_test_01\modle\driver.py", line 23, in browser_chrome
    self.driver=webdriver.Chrome(executable_path=os.path.abspath('..')+'\\Application60\\chromedriver.exe')
  File "C:\Users\pc\AppData\Local\Programs\Python\Python36\lib\site-packages\selenium\webdriver\chrome\webdriver.py", line 73, in __init__
    self.service.start()
  File "C:\Users\pc\AppData\Local\Programs\Python\Python36\lib\site-packages\selenium\webdriver\common\service.py", line 83, in start
    os.path.basename(self.path), self.start_error_message)
selenium.common.exceptions.WebDriverException: Message: 'chromedriver.exe' executable needs to be in PATH. Please see https://sites.google.com/a/chromium.org/chromedriver/home

</pre>
    </div>
    <!--css div popup end-->

    </td>
</tr>

<tr id='ft1.7' class='none'>
    <td class='errorCase'><div class='testcase'>test_delete_shop_search: 商品回收站页面，验证搜索商品编码_retry:1</div></td>
    <td colspan='5' align='center'>

    <!--css div popup start-->
    <a class="popup_link" onfocus='this.blur();' href="javascript:showTestDetail('div_ft1.7')" >
        错误</a>

    <div id='div_ft1.7' class="popup_window">
        <pre>ft1.7: Traceback (most recent call last):
  File "C:\Users\pc\AppData\Local\Programs\Python\Python36\lib\site-packages\selenium\webdriver\common\service.py", line 76, in start
    stdin=PIPE)
  File "C:\Users\pc\AppData\Local\Programs\Python\Python36\lib\subprocess.py", line 709, in __init__
    restore_signals, start_new_session)
  File "C:\Users\pc\AppData\Local\Programs\Python\Python36\lib\subprocess.py", line 997, in _execute_child
    startupinfo)
FileNotFoundError: [WinError 2] 系统找不到指定的文件。

During handling of the above exception, another exception occurred:

Traceback (most recent call last):
  File "G:\Operating_background_test_01\test_case\mytest.py", line 18, in setUp
    self.driver=d.browser_chrome()
  File "G:\Operating_background_test_01\modle\driver.py", line 23, in browser_chrome
    self.driver=webdriver.Chrome(executable_path=os.path.abspath('..')+'\\Application60\\chromedriver.exe')
  File "C:\Users\pc\AppData\Local\Programs\Python\Python36\lib\site-packages\selenium\webdriver\chrome\webdriver.py", line 73, in __init__
    self.service.start()
  File "C:\Users\pc\AppData\Local\Programs\Python\Python36\lib\site-packages\selenium\webdriver\common\service.py", line 83, in start
    os.path.basename(self.path), self.start_error_message)
selenium.common.exceptions.WebDriverException: Message: 'chromedriver.exe' executable needs to be in PATH. Please see https://sites.google.com/a/chromium.org/chromedriver/home

</pre>
    </div>
    <!--css div popup end-->

    </td>
</tr>

<tr id='ft1.8' class='none'>
    <td class='errorCase'><div class='testcase'>test_delete_shops_list_Shop_class: 商品回收站页面，验证以商品分类查询商品_retry:1</div></td>
    <td colspan='5' align='center'>

    <!--css div popup start-->
    <a class="popup_link" onfocus='this.blur();' href="javascript:showTestDetail('div_ft1.8')" >
        错误</a>

    <div id='div_ft1.8' class="popup_window">
        <pre>ft1.8: Traceback (most recent call last):
  File "C:\Users\pc\AppData\Local\Programs\Python\Python36\lib\site-packages\selenium\webdriver\common\service.py", line 76, in start
    stdin=PIPE)
  File "C:\Users\pc\AppData\Local\Programs\Python\Python36\lib\subprocess.py", line 709, in __init__
    restore_signals, start_new_session)
  File "C:\Users\pc\AppData\Local\Programs\Python\Python36\lib\subprocess.py", line 997, in _execute_child
    startupinfo)
FileNotFoundError: [WinError 2] 系统找不到指定的文件。

During handling of the above exception, another exception occurred:

Traceback (most recent call last):
  File "G:\Operating_background_test_01\test_case\mytest.py", line 18, in setUp
    self.driver=d.browser_chrome()
  File "G:\Operating_background_test_01\modle\driver.py", line 23, in browser_chrome
    self.driver=webdriver.Chrome(executable_path=os.path.abspath('..')+'\\Application60\\chromedriver.exe')
  File "C:\Users\pc\AppData\Local\Programs\Python\Python36\lib\site-packages\selenium\webdriver\chrome\webdriver.py", line 73, in __init__
    self.service.start()
  File "C:\Users\pc\AppData\Local\Programs\Python\Python36\lib\site-packages\selenium\webdriver\common\service.py", line 83, in start
    os.path.basename(self.path), self.start_error_message)
selenium.common.exceptions.WebDriverException: Message: 'chromedriver.exe' executable needs to be in PATH. Please see https://sites.google.com/a/chromium.org/chromedriver/home

</pre>
    </div>
    <!--css div popup end-->

    </td>
</tr>

<tr id='ft1.9' class='none'>
    <td class='errorCase'><div class='testcase'>test_delete_shops_list_Shop_name: 商品回收站页面，以商家名称查询商品_retry:1</div></td>
    <td colspan='5' align='center'>

    <!--css div popup start-->
    <a class="popup_link" onfocus='this.blur();' href="javascript:showTestDetail('div_ft1.9')" >
        错误</a>

    <div id='div_ft1.9' class="popup_window">
        <pre>ft1.9: Traceback (most recent call last):
  File "C:\Users\pc\AppData\Local\Programs\Python\Python36\lib\site-packages\selenium\webdriver\common\service.py", line 76, in start
    stdin=PIPE)
  File "C:\Users\pc\AppData\Local\Programs\Python\Python36\lib\subprocess.py", line 709, in __init__
    restore_signals, start_new_session)
  File "C:\Users\pc\AppData\Local\Programs\Python\Python36\lib\subprocess.py", line 997, in _execute_child
    startupinfo)
FileNotFoundError: [WinError 2] 系统找不到指定的文件。

During handling of the above exception, another exception occurred:

Traceback (most recent call last):
  File "G:\Operating_background_test_01\test_case\mytest.py", line 18, in setUp
    self.driver=d.browser_chrome()
  File "G:\Operating_background_test_01\modle\driver.py", line 23, in browser_chrome
    self.driver=webdriver.Chrome(executable_path=os.path.abspath('..')+'\\Application60\\chromedriver.exe')
  File "C:\Users\pc\AppData\Local\Programs\Python\Python36\lib\site-packages\selenium\webdriver\chrome\webdriver.py", line 73, in __init__
    self.service.start()
  File "C:\Users\pc\AppData\Local\Programs\Python\Python36\lib\site-packages\selenium\webdriver\common\service.py", line 83, in start
    os.path.basename(self.path), self.start_error_message)
selenium.common.exceptions.WebDriverException: Message: 'chromedriver.exe' executable needs to be in PATH. Please see https://sites.google.com/a/chromium.org/chromedriver/home

</pre>
    </div>
    <!--css div popup end-->

    </td>
</tr>

<tr id='ft1.10' class='none'>
    <td class='errorCase'><div class='testcase'>test_delete_shops_restore: 商品回收站页面，还原商品_retry:1</div></td>
    <td colspan='5' align='center'>

    <!--css div popup start-->
    <a class="popup_link" onfocus='this.blur();' href="javascript:showTestDetail('div_ft1.10')" >
        错误</a>

    <div id='div_ft1.10' class="popup_window">
        <pre>ft1.10: Traceback (most recent call last):
  File "C:\Users\pc\AppData\Local\Programs\Python\Python36\lib\site-packages\selenium\webdriver\common\service.py", line 76, in start
    stdin=PIPE)
  File "C:\Users\pc\AppData\Local\Programs\Python\Python36\lib\subprocess.py", line 709, in __init__
    restore_signals, start_new_session)
  File "C:\Users\pc\AppData\Local\Programs\Python\Python36\lib\subprocess.py", line 997, in _execute_child
    startupinfo)
FileNotFoundError: [WinError 2] 系统找不到指定的文件。

During handling of the above exception, another exception occurred:

Traceback (most recent call last):
  File "G:\Operating_background_test_01\test_case\mytest.py", line 18, in setUp
    self.driver=d.browser_chrome()
  File "G:\Operating_background_test_01\modle\driver.py", line 23, in browser_chrome
    self.driver=webdriver.Chrome(executable_path=os.path.abspath('..')+'\\Application60\\chromedriver.exe')
  File "C:\Users\pc\AppData\Local\Programs\Python\Python36\lib\site-packages\selenium\webdriver\chrome\webdriver.py", line 73, in __init__
    self.service.start()
  File "C:\Users\pc\AppData\Local\Programs\Python\Python36\lib\site-packages\selenium\webdriver\common\service.py", line 83, in start
    os.path.basename(self.path), self.start_error_message)
selenium.common.exceptions.WebDriverException: Message: 'chromedriver.exe' executable needs to be in PATH. Please see https://sites.google.com/a/chromium.org/chromedriver/home

</pre>
    </div>
    <!--css div popup end-->

    </td>
</tr>

<tr id='ft1.11' class='none'>
    <td class='errorCase'><div class='testcase'>test_goods_class: 商品分类，查询_retry:1</div></td>
    <td colspan='5' align='center'>

    <!--css div popup start-->
    <a class="popup_link" onfocus='this.blur();' href="javascript:showTestDetail('div_ft1.11')" >
        错误</a>

    <div id='div_ft1.11' class="popup_window">
        <pre>ft1.11: Traceback (most recent call last):
  File "C:\Users\pc\AppData\Local\Programs\Python\Python36\lib\site-packages\selenium\webdriver\common\service.py", line 76, in start
    stdin=PIPE)
  File "C:\Users\pc\AppData\Local\Programs\Python\Python36\lib\subprocess.py", line 709, in __init__
    restore_signals, start_new_session)
  File "C:\Users\pc\AppData\Local\Programs\Python\Python36\lib\subprocess.py", line 997, in _execute_child
    startupinfo)
FileNotFoundError: [WinError 2] 系统找不到指定的文件。

During handling of the above exception, another exception occurred:

Traceback (most recent call last):
  File "G:\Operating_background_test_01\test_case\mytest.py", line 18, in setUp
    self.driver=d.browser_chrome()
  File "G:\Operating_background_test_01\modle\driver.py", line 23, in browser_chrome
    self.driver=webdriver.Chrome(executable_path=os.path.abspath('..')+'\\Application60\\chromedriver.exe')
  File "C:\Users\pc\AppData\Local\Programs\Python\Python36\lib\site-packages\selenium\webdriver\chrome\webdriver.py", line 73, in __init__
    self.service.start()
  File "C:\Users\pc\AppData\Local\Programs\Python\Python36\lib\site-packages\selenium\webdriver\common\service.py", line 83, in start
    os.path.basename(self.path), self.start_error_message)
selenium.common.exceptions.WebDriverException: Message: 'chromedriver.exe' executable needs to be in PATH. Please see https://sites.google.com/a/chromium.org/chromedriver/home

</pre>
    </div>
    <!--css div popup end-->

    </td>
</tr>

<tr id='ft1.12' class='none'>
    <td class='errorCase'><div class='testcase'>test_goods_evaluate: 商品评价,按商品名称查询_retry:1</div></td>
    <td colspan='5' align='center'>

    <!--css div popup start-->
    <a class="popup_link" onfocus='this.blur();' href="javascript:showTestDetail('div_ft1.12')" >
        错误</a>

    <div id='div_ft1.12' class="popup_window">
        <pre>ft1.12: Traceback (most recent call last):
  File "C:\Users\pc\AppData\Local\Programs\Python\Python36\lib\site-packages\selenium\webdriver\common\service.py", line 76, in start
    stdin=PIPE)
  File "C:\Users\pc\AppData\Local\Programs\Python\Python36\lib\subprocess.py", line 709, in __init__
    restore_signals, start_new_session)
  File "C:\Users\pc\AppData\Local\Programs\Python\Python36\lib\subprocess.py", line 997, in _execute_child
    startupinfo)
FileNotFoundError: [WinError 2] 系统找不到指定的文件。

During handling of the above exception, another exception occurred:

Traceback (most recent call last):
  File "G:\Operating_background_test_01\test_case\mytest.py", line 18, in setUp
    self.driver=d.browser_chrome()
  File "G:\Operating_background_test_01\modle\driver.py", line 23, in browser_chrome
    self.driver=webdriver.Chrome(executable_path=os.path.abspath('..')+'\\Application60\\chromedriver.exe')
  File "C:\Users\pc\AppData\Local\Programs\Python\Python36\lib\site-packages\selenium\webdriver\chrome\webdriver.py", line 73, in __init__
    self.service.start()
  File "C:\Users\pc\AppData\Local\Programs\Python\Python36\lib\site-packages\selenium\webdriver\common\service.py", line 83, in start
    os.path.basename(self.path), self.start_error_message)
selenium.common.exceptions.WebDriverException: Message: 'chromedriver.exe' executable needs to be in PATH. Please see https://sites.google.com/a/chromium.org/chromedriver/home

</pre>
    </div>
    <!--css div popup end-->

    </td>
</tr>

<tr id='ft1.13' class='none'>
    <td class='errorCase'><div class='testcase'>test_goods_evaluate_delete: 商品评价，删除_retry:1</div></td>
    <td colspan='5' align='center'>

    <!--css div popup start-->
    <a class="popup_link" onfocus='this.blur();' href="javascript:showTestDetail('div_ft1.13')" >
        错误</a>

    <div id='div_ft1.13' class="popup_window">
        <pre>ft1.13: Traceback (most recent call last):
  File "C:\Users\pc\AppData\Local\Programs\Python\Python36\lib\site-packages\selenium\webdriver\common\service.py", line 76, in start
    stdin=PIPE)
  File "C:\Users\pc\AppData\Local\Programs\Python\Python36\lib\subprocess.py", line 709, in __init__
    restore_signals, start_new_session)
  File "C:\Users\pc\AppData\Local\Programs\Python\Python36\lib\subprocess.py", line 997, in _execute_child
    startupinfo)
FileNotFoundError: [WinError 2] 系统找不到指定的文件。

During handling of the above exception, another exception occurred:

Traceback (most recent call last):
  File "G:\Operating_background_test_01\test_case\mytest.py", line 18, in setUp
    self.driver=d.browser_chrome()
  File "G:\Operating_background_test_01\modle\driver.py", line 23, in browser_chrome
    self.driver=webdriver.Chrome(executable_path=os.path.abspath('..')+'\\Application60\\chromedriver.exe')
  File "C:\Users\pc\AppData\Local\Programs\Python\Python36\lib\site-packages\selenium\webdriver\chrome\webdriver.py", line 73, in __init__
    self.service.start()
  File "C:\Users\pc\AppData\Local\Programs\Python\Python36\lib\site-packages\selenium\webdriver\common\service.py", line 83, in start
    os.path.basename(self.path), self.start_error_message)
selenium.common.exceptions.WebDriverException: Message: 'chromedriver.exe' executable needs to be in PATH. Please see https://sites.google.com/a/chromium.org/chromedriver/home

</pre>
    </div>
    <!--css div popup end-->

    </td>
</tr>

<tr id='ft1.14' class='none'>
    <td class='errorCase'><div class='testcase'>test_goods_evaluate_username: 商品评价，按用户昵称查询_retry:1</div></td>
    <td colspan='5' align='center'>

    <!--css div popup start-->
    <a class="popup_link" onfocus='this.blur();' href="javascript:showTestDetail('div_ft1.14')" >
        错误</a>

    <div id='div_ft1.14' class="popup_window">
        <pre>ft1.14: Traceback (most recent call last):
  File "C:\Users\pc\AppData\Local\Programs\Python\Python36\lib\site-packages\selenium\webdriver\common\service.py", line 76, in start
    stdin=PIPE)
  File "C:\Users\pc\AppData\Local\Programs\Python\Python36\lib\subprocess.py", line 709, in __init__
    restore_signals, start_new_session)
  File "C:\Users\pc\AppData\Local\Programs\Python\Python36\lib\subprocess.py", line 997, in _execute_child
    startupinfo)
FileNotFoundError: [WinError 2] 系统找不到指定的文件。

During handling of the above exception, another exception occurred:

Traceback (most recent call last):
  File "G:\Operating_background_test_01\test_case\mytest.py", line 18, in setUp
    self.driver=d.browser_chrome()
  File "G:\Operating_background_test_01\modle\driver.py", line 23, in browser_chrome
    self.driver=webdriver.Chrome(executable_path=os.path.abspath('..')+'\\Application60\\chromedriver.exe')
  File "C:\Users\pc\AppData\Local\Programs\Python\Python36\lib\site-packages\selenium\webdriver\chrome\webdriver.py", line 73, in __init__
    self.service.start()
  File "C:\Users\pc\AppData\Local\Programs\Python\Python36\lib\site-packages\selenium\webdriver\common\service.py", line 83, in start
    os.path.basename(self.path), self.start_error_message)
selenium.common.exceptions.WebDriverException: Message: 'chromedriver.exe' executable needs to be in PATH. Please see https://sites.google.com/a/chromium.org/chromedriver/home

</pre>
    </div>
    <!--css div popup end-->

    </td>
</tr>

<tr id='ft1.15' class='none'>
    <td class='errorCase'><div class='testcase'>test_goods_evaluate_view: 商品评价，查看_retry:1</div></td>
    <td colspan='5' align='center'>

    <!--css div popup start-->
    <a class="popup_link" onfocus='this.blur();' href="javascript:showTestDetail('div_ft1.15')" >
        错误</a>

    <div id='div_ft1.15' class="popup_window">
        <pre>ft1.15: Traceback (most recent call last):
  File "C:\Users\pc\AppData\Local\Programs\Python\Python36\lib\site-packages\selenium\webdriver\common\service.py", line 76, in start
    stdin=PIPE)
  File "C:\Users\pc\AppData\Local\Programs\Python\Python36\lib\subprocess.py", line 709, in __init__
    restore_signals, start_new_session)
  File "C:\Users\pc\AppData\Local\Programs\Python\Python36\lib\subprocess.py", line 997, in _execute_child
    startupinfo)
FileNotFoundError: [WinError 2] 系统找不到指定的文件。

During handling of the above exception, another exception occurred:

Traceback (most recent call last):
  File "G:\Operating_background_test_01\test_case\mytest.py", line 18, in setUp
    self.driver=d.browser_chrome()
  File "G:\Operating_background_test_01\modle\driver.py", line 23, in browser_chrome
    self.driver=webdriver.Chrome(executable_path=os.path.abspath('..')+'\\Application60\\chromedriver.exe')
  File "C:\Users\pc\AppData\Local\Programs\Python\Python36\lib\site-packages\selenium\webdriver\chrome\webdriver.py", line 73, in __init__
    self.service.start()
  File "C:\Users\pc\AppData\Local\Programs\Python\Python36\lib\site-packages\selenium\webdriver\common\service.py", line 83, in start
    os.path.basename(self.path), self.start_error_message)
selenium.common.exceptions.WebDriverException: Message: 'chromedriver.exe' executable needs to be in PATH. Please see https://sites.google.com/a/chromium.org/chromedriver/home

</pre>
    </div>
    <!--css div popup end-->

    </td>
</tr>

<tr id='ft1.16' class='none'>
    <td class='errorCase'><div class='testcase'>test_goods_rows: 商品评价，页面显示条数_retry:1</div></td>
    <td colspan='5' align='center'>

    <!--css div popup start-->
    <a class="popup_link" onfocus='this.blur();' href="javascript:showTestDetail('div_ft1.16')" >
        错误</a>

    <div id='div_ft1.16' class="popup_window">
        <pre>ft1.16: Traceback (most recent call last):
  File "C:\Users\pc\AppData\Local\Programs\Python\Python36\lib\site-packages\selenium\webdriver\common\service.py", line 76, in start
    stdin=PIPE)
  File "C:\Users\pc\AppData\Local\Programs\Python\Python36\lib\subprocess.py", line 709, in __init__
    restore_signals, start_new_session)
  File "C:\Users\pc\AppData\Local\Programs\Python\Python36\lib\subprocess.py", line 997, in _execute_child
    startupinfo)
FileNotFoundError: [WinError 2] 系统找不到指定的文件。

During handling of the above exception, another exception occurred:

Traceback (most recent call last):
  File "G:\Operating_background_test_01\test_case\mytest.py", line 18, in setUp
    self.driver=d.browser_chrome()
  File "G:\Operating_background_test_01\modle\driver.py", line 23, in browser_chrome
    self.driver=webdriver.Chrome(executable_path=os.path.abspath('..')+'\\Application60\\chromedriver.exe')
  File "C:\Users\pc\AppData\Local\Programs\Python\Python36\lib\site-packages\selenium\webdriver\chrome\webdriver.py", line 73, in __init__
    self.service.start()
  File "C:\Users\pc\AppData\Local\Programs\Python\Python36\lib\site-packages\selenium\webdriver\common\service.py", line 83, in start
    os.path.basename(self.path), self.start_error_message)
selenium.common.exceptions.WebDriverException: Message: 'chromedriver.exe' executable needs to be in PATH. Please see https://sites.google.com/a/chromium.org/chromedriver/home

</pre>
    </div>
    <!--css div popup end-->

    </td>
</tr>

<tr id='ft1.17' class='none'>
    <td class='errorCase'><div class='testcase'>test_login_case: 验证登录_retry:1</div></td>
    <td colspan='5' align='center'>

    <!--css div popup start-->
    <a class="popup_link" onfocus='this.blur();' href="javascript:showTestDetail('div_ft1.17')" >
        错误</a>

    <div id='div_ft1.17' class="popup_window">
        <pre>ft1.17: Traceback (most recent call last):
  File "C:\Users\pc\AppData\Local\Programs\Python\Python36\lib\site-packages\selenium\webdriver\common\service.py", line 76, in start
    stdin=PIPE)
  File "C:\Users\pc\AppData\Local\Programs\Python\Python36\lib\subprocess.py", line 709, in __init__
    restore_signals, start_new_session)
  File "C:\Users\pc\AppData\Local\Programs\Python\Python36\lib\subprocess.py", line 997, in _execute_child
    startupinfo)
FileNotFoundError: [WinError 2] 系统找不到指定的文件。

During handling of the above exception, another exception occurred:

Traceback (most recent call last):
  File "G:\Operating_background_test_01\test_case\mytest.py", line 18, in setUp
    self.driver=d.browser_chrome()
  File "G:\Operating_background_test_01\modle\driver.py", line 23, in browser_chrome
    self.driver=webdriver.Chrome(executable_path=os.path.abspath('..')+'\\Application60\\chromedriver.exe')
  File "C:\Users\pc\AppData\Local\Programs\Python\Python36\lib\site-packages\selenium\webdriver\chrome\webdriver.py", line 73, in __init__
    self.service.start()
  File "C:\Users\pc\AppData\Local\Programs\Python\Python36\lib\site-packages\selenium\webdriver\common\service.py", line 83, in start
    os.path.basename(self.path), self.start_error_message)
selenium.common.exceptions.WebDriverException: Message: 'chromedriver.exe' executable needs to be in PATH. Please see https://sites.google.com/a/chromium.org/chromedriver/home

</pre>
    </div>
    <!--css div popup end-->

    </td>
</tr>

<tr id='ft1.18' class='none'>
    <td class='errorCase'><div class='testcase'>test_page_break: 验证切换分页下拉框_retry:1</div></td>
    <td colspan='5' align='center'>

    <!--css div popup start-->
    <a class="popup_link" onfocus='this.blur();' href="javascript:showTestDetail('div_ft1.18')" >
        错误</a>

    <div id='div_ft1.18' class="popup_window">
        <pre>ft1.18: Traceback (most recent call last):
  File "C:\Users\pc\AppData\Local\Programs\Python\Python36\lib\site-packages\selenium\webdriver\common\service.py", line 76, in start
    stdin=PIPE)
  File "C:\Users\pc\AppData\Local\Programs\Python\Python36\lib\subprocess.py", line 709, in __init__
    restore_signals, start_new_session)
  File "C:\Users\pc\AppData\Local\Programs\Python\Python36\lib\subprocess.py", line 997, in _execute_child
    startupinfo)
FileNotFoundError: [WinError 2] 系统找不到指定的文件。

During handling of the above exception, another exception occurred:

Traceback (most recent call last):
  File "G:\Operating_background_test_01\test_case\mytest.py", line 18, in setUp
    self.driver=d.browser_chrome()
  File "G:\Operating_background_test_01\modle\driver.py", line 23, in browser_chrome
    self.driver=webdriver.Chrome(executable_path=os.path.abspath('..')+'\\Application60\\chromedriver.exe')
  File "C:\Users\pc\AppData\Local\Programs\Python\Python36\lib\site-packages\selenium\webdriver\chrome\webdriver.py", line 73, in __init__
    self.service.start()
  File "C:\Users\pc\AppData\Local\Programs\Python\Python36\lib\site-packages\selenium\webdriver\common\service.py", line 83, in start
    os.path.basename(self.path), self.start_error_message)
selenium.common.exceptions.WebDriverException: Message: 'chromedriver.exe' executable needs to be in PATH. Please see https://sites.google.com/a/chromium.org/chromedriver/home

</pre>
    </div>
    <!--css div popup end-->

    </td>
</tr>

<tr id='ft1.19' class='none'>
    <td class='errorCase'><div class='testcase'>test_putaway_shop: 点击上架按钮_retry:1</div></td>
    <td colspan='5' align='center'>

    <!--css div popup start-->
    <a class="popup_link" onfocus='this.blur();' href="javascript:showTestDetail('div_ft1.19')" >
        错误</a>

    <div id='div_ft1.19' class="popup_window">
        <pre>ft1.19: Traceback (most recent call last):
  File "C:\Users\pc\AppData\Local\Programs\Python\Python36\lib\site-packages\selenium\webdriver\common\service.py", line 76, in start
    stdin=PIPE)
  File "C:\Users\pc\AppData\Local\Programs\Python\Python36\lib\subprocess.py", line 709, in __init__
    restore_signals, start_new_session)
  File "C:\Users\pc\AppData\Local\Programs\Python\Python36\lib\subprocess.py", line 997, in _execute_child
    startupinfo)
FileNotFoundError: [WinError 2] 系统找不到指定的文件。

During handling of the above exception, another exception occurred:

Traceback (most recent call last):
  File "G:\Operating_background_test_01\test_case\mytest.py", line 18, in setUp
    self.driver=d.browser_chrome()
  File "G:\Operating_background_test_01\modle\driver.py", line 23, in browser_chrome
    self.driver=webdriver.Chrome(executable_path=os.path.abspath('..')+'\\Application60\\chromedriver.exe')
  File "C:\Users\pc\AppData\Local\Programs\Python\Python36\lib\site-packages\selenium\webdriver\chrome\webdriver.py", line 73, in __init__
    self.service.start()
  File "C:\Users\pc\AppData\Local\Programs\Python\Python36\lib\site-packages\selenium\webdriver\common\service.py", line 83, in start
    os.path.basename(self.path), self.start_error_message)
selenium.common.exceptions.WebDriverException: Message: 'chromedriver.exe' executable needs to be in PATH. Please see https://sites.google.com/a/chromium.org/chromedriver/home

</pre>
    </div>
    <!--css div popup end-->

    </td>
</tr>

<tr id='ft1.20' class='none'>
    <td class='errorCase'><div class='testcase'>test_revise_food_stamps: 修改粮票规则_retry:1</div></td>
    <td colspan='5' align='center'>

    <!--css div popup start-->
    <a class="popup_link" onfocus='this.blur();' href="javascript:showTestDetail('div_ft1.20')" >
        错误</a>

    <div id='div_ft1.20' class="popup_window">
        <pre>ft1.20: Traceback (most recent call last):
  File "C:\Users\pc\AppData\Local\Programs\Python\Python36\lib\site-packages\selenium\webdriver\common\service.py", line 76, in start
    stdin=PIPE)
  File "C:\Users\pc\AppData\Local\Programs\Python\Python36\lib\subprocess.py", line 709, in __init__
    restore_signals, start_new_session)
  File "C:\Users\pc\AppData\Local\Programs\Python\Python36\lib\subprocess.py", line 997, in _execute_child
    startupinfo)
FileNotFoundError: [WinError 2] 系统找不到指定的文件。

During handling of the above exception, another exception occurred:

Traceback (most recent call last):
  File "G:\Operating_background_test_01\test_case\mytest.py", line 18, in setUp
    self.driver=d.browser_chrome()
  File "G:\Operating_background_test_01\modle\driver.py", line 23, in browser_chrome
    self.driver=webdriver.Chrome(executable_path=os.path.abspath('..')+'\\Application60\\chromedriver.exe')
  File "C:\Users\pc\AppData\Local\Programs\Python\Python36\lib\site-packages\selenium\webdriver\chrome\webdriver.py", line 73, in __init__
    self.service.start()
  File "C:\Users\pc\AppData\Local\Programs\Python\Python36\lib\site-packages\selenium\webdriver\common\service.py", line 83, in start
    os.path.basename(self.path), self.start_error_message)
selenium.common.exceptions.WebDriverException: Message: 'chromedriver.exe' executable needs to be in PATH. Please see https://sites.google.com/a/chromium.org/chromedriver/home

</pre>
    </div>
    <!--css div popup end-->

    </td>
</tr>

<tr id='ft1.21' class='none'>
    <td class='errorCase'><div class='testcase'>test_shops_list_In_the_shelf: 验证商品列表，上架中商品_retry:1</div></td>
    <td colspan='5' align='center'>

    <!--css div popup start-->
    <a class="popup_link" onfocus='this.blur();' href="javascript:showTestDetail('div_ft1.21')" >
        错误</a>

    <div id='div_ft1.21' class="popup_window">
        <pre>ft1.21: Traceback (most recent call last):
  File "C:\Users\pc\AppData\Local\Programs\Python\Python36\lib\site-packages\selenium\webdriver\common\service.py", line 76, in start
    stdin=PIPE)
  File "C:\Users\pc\AppData\Local\Programs\Python\Python36\lib\subprocess.py", line 709, in __init__
    restore_signals, start_new_session)
  File "C:\Users\pc\AppData\Local\Programs\Python\Python36\lib\subprocess.py", line 997, in _execute_child
    startupinfo)
FileNotFoundError: [WinError 2] 系统找不到指定的文件。

During handling of the above exception, another exception occurred:

Traceback (most recent call last):
  File "G:\Operating_background_test_01\test_case\mytest.py", line 18, in setUp
    self.driver=d.browser_chrome()
  File "G:\Operating_background_test_01\modle\driver.py", line 23, in browser_chrome
    self.driver=webdriver.Chrome(executable_path=os.path.abspath('..')+'\\Application60\\chromedriver.exe')
  File "C:\Users\pc\AppData\Local\Programs\Python\Python36\lib\site-packages\selenium\webdriver\chrome\webdriver.py", line 73, in __init__
    self.service.start()
  File "C:\Users\pc\AppData\Local\Programs\Python\Python36\lib\site-packages\selenium\webdriver\common\service.py", line 83, in start
    os.path.basename(self.path), self.start_error_message)
selenium.common.exceptions.WebDriverException: Message: 'chromedriver.exe' executable needs to be in PATH. Please see https://sites.google.com/a/chromium.org/chromedriver/home

</pre>
    </div>
    <!--css div popup end-->

    </td>
</tr>

<tr id='ft1.22' class='none'>
    <td class='errorCase'><div class='testcase'>test_shops_list_Shop_class: 以商品分类查询商品_retry:1</div></td>
    <td colspan='5' align='center'>

    <!--css div popup start-->
    <a class="popup_link" onfocus='this.blur();' href="javascript:showTestDetail('div_ft1.22')" >
        错误</a>

    <div id='div_ft1.22' class="popup_window">
        <pre>ft1.22: Traceback (most recent call last):
  File "C:\Users\pc\AppData\Local\Programs\Python\Python36\lib\site-packages\selenium\webdriver\common\service.py", line 76, in start
    stdin=PIPE)
  File "C:\Users\pc\AppData\Local\Programs\Python\Python36\lib\subprocess.py", line 709, in __init__
    restore_signals, start_new_session)
  File "C:\Users\pc\AppData\Local\Programs\Python\Python36\lib\subprocess.py", line 997, in _execute_child
    startupinfo)
FileNotFoundError: [WinError 2] 系统找不到指定的文件。

During handling of the above exception, another exception occurred:

Traceback (most recent call last):
  File "G:\Operating_background_test_01\test_case\mytest.py", line 18, in setUp
    self.driver=d.browser_chrome()
  File "G:\Operating_background_test_01\modle\driver.py", line 23, in browser_chrome
    self.driver=webdriver.Chrome(executable_path=os.path.abspath('..')+'\\Application60\\chromedriver.exe')
  File "C:\Users\pc\AppData\Local\Programs\Python\Python36\lib\site-packages\selenium\webdriver\chrome\webdriver.py", line 73, in __init__
    self.service.start()
  File "C:\Users\pc\AppData\Local\Programs\Python\Python36\lib\site-packages\selenium\webdriver\common\service.py", line 83, in start
    os.path.basename(self.path), self.start_error_message)
selenium.common.exceptions.WebDriverException: Message: 'chromedriver.exe' executable needs to be in PATH. Please see https://sites.google.com/a/chromium.org/chromedriver/home

</pre>
    </div>
    <!--css div popup end-->

    </td>
</tr>

<tr id='ft1.23' class='none'>
    <td class='errorCase'><div class='testcase'>test_shops_list_Shop_name: 以商家名称查询商品_retry:1</div></td>
    <td colspan='5' align='center'>

    <!--css div popup start-->
    <a class="popup_link" onfocus='this.blur();' href="javascript:showTestDetail('div_ft1.23')" >
        错误</a>

    <div id='div_ft1.23' class="popup_window">
        <pre>ft1.23: Traceback (most recent call last):
  File "C:\Users\pc\AppData\Local\Programs\Python\Python36\lib\site-packages\selenium\webdriver\common\service.py", line 76, in start
    stdin=PIPE)
  File "C:\Users\pc\AppData\Local\Programs\Python\Python36\lib\subprocess.py", line 709, in __init__
    restore_signals, start_new_session)
  File "C:\Users\pc\AppData\Local\Programs\Python\Python36\lib\subprocess.py", line 997, in _execute_child
    startupinfo)
FileNotFoundError: [WinError 2] 系统找不到指定的文件。

During handling of the above exception, another exception occurred:

Traceback (most recent call last):
  File "G:\Operating_background_test_01\test_case\mytest.py", line 18, in setUp
    self.driver=d.browser_chrome()
  File "G:\Operating_background_test_01\modle\driver.py", line 23, in browser_chrome
    self.driver=webdriver.Chrome(executable_path=os.path.abspath('..')+'\\Application60\\chromedriver.exe')
  File "C:\Users\pc\AppData\Local\Programs\Python\Python36\lib\site-packages\selenium\webdriver\chrome\webdriver.py", line 73, in __init__
    self.service.start()
  File "C:\Users\pc\AppData\Local\Programs\Python\Python36\lib\site-packages\selenium\webdriver\common\service.py", line 83, in start
    os.path.basename(self.path), self.start_error_message)
selenium.common.exceptions.WebDriverException: Message: 'chromedriver.exe' executable needs to be in PATH. Please see https://sites.google.com/a/chromium.org/chromedriver/home

</pre>
    </div>
    <!--css div popup end-->

    </td>
</tr>

<tr id='ft1.24' class='none'>
    <td class='errorCase'><div class='testcase'>test_shops_list_The_shelves: 验证商品列表，下架中商品_retry:1</div></td>
    <td colspan='5' align='center'>

    <!--css div popup start-->
    <a class="popup_link" onfocus='this.blur();' href="javascript:showTestDetail('div_ft1.24')" >
        错误</a>

    <div id='div_ft1.24' class="popup_window">
        <pre>ft1.24: Traceback (most recent call last):
  File "C:\Users\pc\AppData\Local\Programs\Python\Python36\lib\site-packages\selenium\webdriver\common\service.py", line 76, in start
    stdin=PIPE)
  File "C:\Users\pc\AppData\Local\Programs\Python\Python36\lib\subprocess.py", line 709, in __init__
    restore_signals, start_new_session)
  File "C:\Users\pc\AppData\Local\Programs\Python\Python36\lib\subprocess.py", line 997, in _execute_child
    startupinfo)
FileNotFoundError: [WinError 2] 系统找不到指定的文件。

During handling of the above exception, another exception occurred:

Traceback (most recent call last):
  File "G:\Operating_background_test_01\test_case\mytest.py", line 18, in setUp
    self.driver=d.browser_chrome()
  File "G:\Operating_background_test_01\modle\driver.py", line 23, in browser_chrome
    self.driver=webdriver.Chrome(executable_path=os.path.abspath('..')+'\\Application60\\chromedriver.exe')
  File "C:\Users\pc\AppData\Local\Programs\Python\Python36\lib\site-packages\selenium\webdriver\chrome\webdriver.py", line 73, in __init__
    self.service.start()
  File "C:\Users\pc\AppData\Local\Programs\Python\Python36\lib\site-packages\selenium\webdriver\common\service.py", line 83, in start
    os.path.basename(self.path), self.start_error_message)
selenium.common.exceptions.WebDriverException: Message: 'chromedriver.exe' executable needs to be in PATH. Please see https://sites.google.com/a/chromium.org/chromedriver/home

</pre>
    </div>
    <!--css div popup end-->

    </td>
</tr>

<tr id='ft1.25' class='none'>
    <td class='errorCase'><div class='testcase'>test_shops_list_To_audit: 验证商品列表，待审核商品_retry:1</div></td>
    <td colspan='5' align='center'>

    <!--css div popup start-->
    <a class="popup_link" onfocus='this.blur();' href="javascript:showTestDetail('div_ft1.25')" >
        错误</a>

    <div id='div_ft1.25' class="popup_window">
        <pre>ft1.25: Traceback (most recent call last):
  File "C:\Users\pc\AppData\Local\Programs\Python\Python36\lib\site-packages\selenium\webdriver\common\service.py", line 76, in start
    stdin=PIPE)
  File "C:\Users\pc\AppData\Local\Programs\Python\Python36\lib\subprocess.py", line 709, in __init__
    restore_signals, start_new_session)
  File "C:\Users\pc\AppData\Local\Programs\Python\Python36\lib\subprocess.py", line 997, in _execute_child
    startupinfo)
FileNotFoundError: [WinError 2] 系统找不到指定的文件。

During handling of the above exception, another exception occurred:

Traceback (most recent call last):
  File "G:\Operating_background_test_01\test_case\mytest.py", line 18, in setUp
    self.driver=d.browser_chrome()
  File "G:\Operating_background_test_01\modle\driver.py", line 23, in browser_chrome
    self.driver=webdriver.Chrome(executable_path=os.path.abspath('..')+'\\Application60\\chromedriver.exe')
  File "C:\Users\pc\AppData\Local\Programs\Python\Python36\lib\site-packages\selenium\webdriver\chrome\webdriver.py", line 73, in __init__
    self.service.start()
  File "C:\Users\pc\AppData\Local\Programs\Python\Python36\lib\site-packages\selenium\webdriver\common\service.py", line 83, in start
    os.path.basename(self.path), self.start_error_message)
selenium.common.exceptions.WebDriverException: Message: 'chromedriver.exe' executable needs to be in PATH. Please see https://sites.google.com/a/chromium.org/chromedriver/home

</pre>
    </div>
    <!--css div popup end-->

    </td>
</tr>

<tr id='ft1.26' class='none'>
    <td class='errorCase'><div class='testcase'>test_shops_list_allshops: 验证商品列表，全部商品_retry:1</div></td>
    <td colspan='5' align='center'>

    <!--css div popup start-->
    <a class="popup_link" onfocus='this.blur();' href="javascript:showTestDetail('div_ft1.26')" >
        错误</a>

    <div id='div_ft1.26' class="popup_window">
        <pre>ft1.26: Traceback (most recent call last):
  File "C:\Users\pc\AppData\Local\Programs\Python\Python36\lib\site-packages\selenium\webdriver\common\service.py", line 76, in start
    stdin=PIPE)
  File "C:\Users\pc\AppData\Local\Programs\Python\Python36\lib\subprocess.py", line 709, in __init__
    restore_signals, start_new_session)
  File "C:\Users\pc\AppData\Local\Programs\Python\Python36\lib\subprocess.py", line 997, in _execute_child
    startupinfo)
FileNotFoundError: [WinError 2] 系统找不到指定的文件。

During handling of the above exception, another exception occurred:

Traceback (most recent call last):
  File "G:\Operating_background_test_01\test_case\mytest.py", line 18, in setUp
    self.driver=d.browser_chrome()
  File "G:\Operating_background_test_01\modle\driver.py", line 23, in browser_chrome
    self.driver=webdriver.Chrome(executable_path=os.path.abspath('..')+'\\Application60\\chromedriver.exe')
  File "C:\Users\pc\AppData\Local\Programs\Python\Python36\lib\site-packages\selenium\webdriver\chrome\webdriver.py", line 73, in __init__
    self.service.start()
  File "C:\Users\pc\AppData\Local\Programs\Python\Python36\lib\site-packages\selenium\webdriver\common\service.py", line 83, in start
    os.path.basename(self.path), self.start_error_message)
selenium.common.exceptions.WebDriverException: Message: 'chromedriver.exe' executable needs to be in PATH. Please see https://sites.google.com/a/chromium.org/chromedriver/home

</pre>
    </div>
    <!--css div popup end-->

    </td>
</tr>

<tr id='ft1.27' class='none'>
    <td class='errorCase'><div class='testcase'>test_shops_list_approve: 验证商品列表，审核通过_retry:1</div></td>
    <td colspan='5' align='center'>

    <!--css div popup start-->
    <a class="popup_link" onfocus='this.blur();' href="javascript:showTestDetail('div_ft1.27')" >
        错误</a>

    <div id='div_ft1.27' class="popup_window">
        <pre>ft1.27: Traceback (most recent call last):
  File "C:\Users\pc\AppData\Local\Programs\Python\Python36\lib\site-packages\selenium\webdriver\common\service.py", line 76, in start
    stdin=PIPE)
  File "C:\Users\pc\AppData\Local\Programs\Python\Python36\lib\subprocess.py", line 709, in __init__
    restore_signals, start_new_session)
  File "C:\Users\pc\AppData\Local\Programs\Python\Python36\lib\subprocess.py", line 997, in _execute_child
    startupinfo)
FileNotFoundError: [WinError 2] 系统找不到指定的文件。

During handling of the above exception, another exception occurred:

Traceback (most recent call last):
  File "G:\Operating_background_test_01\test_case\mytest.py", line 18, in setUp
    self.driver=d.browser_chrome()
  File "G:\Operating_background_test_01\modle\driver.py", line 23, in browser_chrome
    self.driver=webdriver.Chrome(executable_path=os.path.abspath('..')+'\\Application60\\chromedriver.exe')
  File "C:\Users\pc\AppData\Local\Programs\Python\Python36\lib\site-packages\selenium\webdriver\chrome\webdriver.py", line 73, in __init__
    self.service.start()
  File "C:\Users\pc\AppData\Local\Programs\Python\Python36\lib\site-packages\selenium\webdriver\common\service.py", line 83, in start
    os.path.basename(self.path), self.start_error_message)
selenium.common.exceptions.WebDriverException: Message: 'chromedriver.exe' executable needs to be in PATH. Please see https://sites.google.com/a/chromium.org/chromedriver/home

</pre>
    </div>
    <!--css div popup end-->

    </td>
</tr>

<tr id='ft1.28' class='none'>
    <td class='errorCase'><div class='testcase'>test_shops_list_disapprove: 验证商品列表，审核不通过_retry:1</div></td>
    <td colspan='5' align='center'>

    <!--css div popup start-->
    <a class="popup_link" onfocus='this.blur();' href="javascript:showTestDetail('div_ft1.28')" >
        错误</a>

    <div id='div_ft1.28' class="popup_window">
        <pre>ft1.28: Traceback (most recent call last):
  File "C:\Users\pc\AppData\Local\Programs\Python\Python36\lib\site-packages\selenium\webdriver\common\service.py", line 76, in start
    stdin=PIPE)
  File "C:\Users\pc\AppData\Local\Programs\Python\Python36\lib\subprocess.py", line 709, in __init__
    restore_signals, start_new_session)
  File "C:\Users\pc\AppData\Local\Programs\Python\Python36\lib\subprocess.py", line 997, in _execute_child
    startupinfo)
FileNotFoundError: [WinError 2] 系统找不到指定的文件。

During handling of the above exception, another exception occurred:

Traceback (most recent call last):
  File "G:\Operating_background_test_01\test_case\mytest.py", line 18, in setUp
    self.driver=d.browser_chrome()
  File "G:\Operating_background_test_01\modle\driver.py", line 23, in browser_chrome
    self.driver=webdriver.Chrome(executable_path=os.path.abspath('..')+'\\Application60\\chromedriver.exe')
  File "C:\Users\pc\AppData\Local\Programs\Python\Python36\lib\site-packages\selenium\webdriver\chrome\webdriver.py", line 73, in __init__
    self.service.start()
  File "C:\Users\pc\AppData\Local\Programs\Python\Python36\lib\site-packages\selenium\webdriver\common\service.py", line 83, in start
    os.path.basename(self.path), self.start_error_message)
selenium.common.exceptions.WebDriverException: Message: 'chromedriver.exe' executable needs to be in PATH. Please see https://sites.google.com/a/chromium.org/chromedriver/home

</pre>
    </div>
    <!--css div popup end-->

    </td>
</tr>

<tr id='ft1.29' class='none'>
    <td class='errorCase'><div class='testcase'>test_shops_list_group_query1: 上架中，以编号，分类，名称查询商品_retry:1</div></td>
    <td colspan='5' align='center'>

    <!--css div popup start-->
    <a class="popup_link" onfocus='this.blur();' href="javascript:showTestDetail('div_ft1.29')" >
        错误</a>

    <div id='div_ft1.29' class="popup_window">
        <pre>ft1.29: Traceback (most recent call last):
  File "C:\Users\pc\AppData\Local\Programs\Python\Python36\lib\site-packages\selenium\webdriver\common\service.py", line 76, in start
    stdin=PIPE)
  File "C:\Users\pc\AppData\Local\Programs\Python\Python36\lib\subprocess.py", line 709, in __init__
    restore_signals, start_new_session)
  File "C:\Users\pc\AppData\Local\Programs\Python\Python36\lib\subprocess.py", line 997, in _execute_child
    startupinfo)
FileNotFoundError: [WinError 2] 系统找不到指定的文件。

During handling of the above exception, another exception occurred:

Traceback (most recent call last):
  File "G:\Operating_background_test_01\test_case\mytest.py", line 18, in setUp
    self.driver=d.browser_chrome()
  File "G:\Operating_background_test_01\modle\driver.py", line 23, in browser_chrome
    self.driver=webdriver.Chrome(executable_path=os.path.abspath('..')+'\\Application60\\chromedriver.exe')
  File "C:\Users\pc\AppData\Local\Programs\Python\Python36\lib\site-packages\selenium\webdriver\chrome\webdriver.py", line 73, in __init__
    self.service.start()
  File "C:\Users\pc\AppData\Local\Programs\Python\Python36\lib\site-packages\selenium\webdriver\common\service.py", line 83, in start
    os.path.basename(self.path), self.start_error_message)
selenium.common.exceptions.WebDriverException: Message: 'chromedriver.exe' executable needs to be in PATH. Please see https://sites.google.com/a/chromium.org/chromedriver/home

</pre>
    </div>
    <!--css div popup end-->

    </td>
</tr>

<tr id='ft1.30' class='none'>
    <td class='errorCase'><div class='testcase'>test_shops_list_group_query2: 下架中，以编号，分类，名称查询商品_retry:1</div></td>
    <td colspan='5' align='center'>

    <!--css div popup start-->
    <a class="popup_link" onfocus='this.blur();' href="javascript:showTestDetail('div_ft1.30')" >
        错误</a>

    <div id='div_ft1.30' class="popup_window">
        <pre>ft1.30: Traceback (most recent call last):
  File "C:\Users\pc\AppData\Local\Programs\Python\Python36\lib\site-packages\selenium\webdriver\common\service.py", line 76, in start
    stdin=PIPE)
  File "C:\Users\pc\AppData\Local\Programs\Python\Python36\lib\subprocess.py", line 709, in __init__
    restore_signals, start_new_session)
  File "C:\Users\pc\AppData\Local\Programs\Python\Python36\lib\subprocess.py", line 997, in _execute_child
    startupinfo)
FileNotFoundError: [WinError 2] 系统找不到指定的文件。

During handling of the above exception, another exception occurred:

Traceback (most recent call last):
  File "G:\Operating_background_test_01\test_case\mytest.py", line 18, in setUp
    self.driver=d.browser_chrome()
  File "G:\Operating_background_test_01\modle\driver.py", line 23, in browser_chrome
    self.driver=webdriver.Chrome(executable_path=os.path.abspath('..')+'\\Application60\\chromedriver.exe')
  File "C:\Users\pc\AppData\Local\Programs\Python\Python36\lib\site-packages\selenium\webdriver\chrome\webdriver.py", line 73, in __init__
    self.service.start()
  File "C:\Users\pc\AppData\Local\Programs\Python\Python36\lib\site-packages\selenium\webdriver\common\service.py", line 83, in start
    os.path.basename(self.path), self.start_error_message)
selenium.common.exceptions.WebDriverException: Message: 'chromedriver.exe' executable needs to be in PATH. Please see https://sites.google.com/a/chromium.org/chromedriver/home

</pre>
    </div>
    <!--css div popup end-->

    </td>
</tr>

<tr id='ft1.31' class='none'>
    <td class='errorCase'><div class='testcase'>test_shops_list_group_query3: 待审核，以编号，分类，名称查询商品_retry:1</div></td>
    <td colspan='5' align='center'>

    <!--css div popup start-->
    <a class="popup_link" onfocus='this.blur();' href="javascript:showTestDetail('div_ft1.31')" >
        错误</a>

    <div id='div_ft1.31' class="popup_window">
        <pre>ft1.31: Traceback (most recent call last):
  File "C:\Users\pc\AppData\Local\Programs\Python\Python36\lib\site-packages\selenium\webdriver\common\service.py", line 76, in start
    stdin=PIPE)
  File "C:\Users\pc\AppData\Local\Programs\Python\Python36\lib\subprocess.py", line 709, in __init__
    restore_signals, start_new_session)
  File "C:\Users\pc\AppData\Local\Programs\Python\Python36\lib\subprocess.py", line 997, in _execute_child
    startupinfo)
FileNotFoundError: [WinError 2] 系统找不到指定的文件。

During handling of the above exception, another exception occurred:

Traceback (most recent call last):
  File "G:\Operating_background_test_01\test_case\mytest.py", line 18, in setUp
    self.driver=d.browser_chrome()
  File "G:\Operating_background_test_01\modle\driver.py", line 23, in browser_chrome
    self.driver=webdriver.Chrome(executable_path=os.path.abspath('..')+'\\Application60\\chromedriver.exe')
  File "C:\Users\pc\AppData\Local\Programs\Python\Python36\lib\site-packages\selenium\webdriver\chrome\webdriver.py", line 73, in __init__
    self.service.start()
  File "C:\Users\pc\AppData\Local\Programs\Python\Python36\lib\site-packages\selenium\webdriver\common\service.py", line 83, in start
    os.path.basename(self.path), self.start_error_message)
selenium.common.exceptions.WebDriverException: Message: 'chromedriver.exe' executable needs to be in PATH. Please see https://sites.google.com/a/chromium.org/chromedriver/home

</pre>
    </div>
    <!--css div popup end-->

    </td>
</tr>

<tr id='ft1.32' class='none'>
    <td class='errorCase'><div class='testcase'>test_shops_list_group_query4: 审核通过，以编号，分类，名称查询商品_retry:1</div></td>
    <td colspan='5' align='center'>

    <!--css div popup start-->
    <a class="popup_link" onfocus='this.blur();' href="javascript:showTestDetail('div_ft1.32')" >
        错误</a>

    <div id='div_ft1.32' class="popup_window">
        <pre>ft1.32: Traceback (most recent call last):
  File "C:\Users\pc\AppData\Local\Programs\Python\Python36\lib\site-packages\selenium\webdriver\common\service.py", line 76, in start
    stdin=PIPE)
  File "C:\Users\pc\AppData\Local\Programs\Python\Python36\lib\subprocess.py", line 709, in __init__
    restore_signals, start_new_session)
  File "C:\Users\pc\AppData\Local\Programs\Python\Python36\lib\subprocess.py", line 997, in _execute_child
    startupinfo)
FileNotFoundError: [WinError 2] 系统找不到指定的文件。

During handling of the above exception, another exception occurred:

Traceback (most recent call last):
  File "G:\Operating_background_test_01\test_case\mytest.py", line 18, in setUp
    self.driver=d.browser_chrome()
  File "G:\Operating_background_test_01\modle\driver.py", line 23, in browser_chrome
    self.driver=webdriver.Chrome(executable_path=os.path.abspath('..')+'\\Application60\\chromedriver.exe')
  File "C:\Users\pc\AppData\Local\Programs\Python\Python36\lib\site-packages\selenium\webdriver\chrome\webdriver.py", line 73, in __init__
    self.service.start()
  File "C:\Users\pc\AppData\Local\Programs\Python\Python36\lib\site-packages\selenium\webdriver\common\service.py", line 83, in start
    os.path.basename(self.path), self.start_error_message)
selenium.common.exceptions.WebDriverException: Message: 'chromedriver.exe' executable needs to be in PATH. Please see https://sites.google.com/a/chromium.org/chromedriver/home

</pre>
    </div>
    <!--css div popup end-->

    </td>
</tr>

<tr id='ft1.33' class='none'>
    <td class='errorCase'><div class='testcase'>test_shops_list_group_query5: 审核不通过，以编号，分类，名称查询商品_retry:1</div></td>
    <td colspan='5' align='center'>

    <!--css div popup start-->
    <a class="popup_link" onfocus='this.blur();' href="javascript:showTestDetail('div_ft1.33')" >
        错误</a>

    <div id='div_ft1.33' class="popup_window">
        <pre>ft1.33: Traceback (most recent call last):
  File "C:\Users\pc\AppData\Local\Programs\Python\Python36\lib\site-packages\selenium\webdriver\common\service.py", line 76, in start
    stdin=PIPE)
  File "C:\Users\pc\AppData\Local\Programs\Python\Python36\lib\subprocess.py", line 709, in __init__
    restore_signals, start_new_session)
  File "C:\Users\pc\AppData\Local\Programs\Python\Python36\lib\subprocess.py", line 997, in _execute_child
    startupinfo)
FileNotFoundError: [WinError 2] 系统找不到指定的文件。

During handling of the above exception, another exception occurred:

Traceback (most recent call last):
  File "G:\Operating_background_test_01\test_case\mytest.py", line 18, in setUp
    self.driver=d.browser_chrome()
  File "G:\Operating_background_test_01\modle\driver.py", line 23, in browser_chrome
    self.driver=webdriver.Chrome(executable_path=os.path.abspath('..')+'\\Application60\\chromedriver.exe')
  File "C:\Users\pc\AppData\Local\Programs\Python\Python36\lib\site-packages\selenium\webdriver\chrome\webdriver.py", line 73, in __init__
    self.service.start()
  File "C:\Users\pc\AppData\Local\Programs\Python\Python36\lib\site-packages\selenium\webdriver\common\service.py", line 83, in start
    os.path.basename(self.path), self.start_error_message)
selenium.common.exceptions.WebDriverException: Message: 'chromedriver.exe' executable needs to be in PATH. Please see https://sites.google.com/a/chromium.org/chromedriver/home

</pre>
    </div>
    <!--css div popup end-->

    </td>
</tr>

<tr id='ft1.34' class='none'>
    <td class='errorCase'><div class='testcase'>test_shops_list_group_query6: 售罄，以编号，分类，名称查询商品_retry:1</div></td>
    <td colspan='5' align='center'>

    <!--css div popup start-->
    <a class="popup_link" onfocus='this.blur();' href="javascript:showTestDetail('div_ft1.34')" >
        错误</a>

    <div id='div_ft1.34' class="popup_window">
        <pre>ft1.34: Traceback (most recent call last):
  File "C:\Users\pc\AppData\Local\Programs\Python\Python36\lib\site-packages\selenium\webdriver\common\service.py", line 76, in start
    stdin=PIPE)
  File "C:\Users\pc\AppData\Local\Programs\Python\Python36\lib\subprocess.py", line 709, in __init__
    restore_signals, start_new_session)
  File "C:\Users\pc\AppData\Local\Programs\Python\Python36\lib\subprocess.py", line 997, in _execute_child
    startupinfo)
FileNotFoundError: [WinError 2] 系统找不到指定的文件。

During handling of the above exception, another exception occurred:

Traceback (most recent call last):
  File "G:\Operating_background_test_01\test_case\mytest.py", line 18, in setUp
    self.driver=d.browser_chrome()
  File "G:\Operating_background_test_01\modle\driver.py", line 23, in browser_chrome
    self.driver=webdriver.Chrome(executable_path=os.path.abspath('..')+'\\Application60\\chromedriver.exe')
  File "C:\Users\pc\AppData\Local\Programs\Python\Python36\lib\site-packages\selenium\webdriver\chrome\webdriver.py", line 73, in __init__
    self.service.start()
  File "C:\Users\pc\AppData\Local\Programs\Python\Python36\lib\site-packages\selenium\webdriver\common\service.py", line 83, in start
    os.path.basename(self.path), self.start_error_message)
selenium.common.exceptions.WebDriverException: Message: 'chromedriver.exe' executable needs to be in PATH. Please see https://sites.google.com/a/chromium.org/chromedriver/home

</pre>
    </div>
    <!--css div popup end-->

    </td>
</tr>

<tr id='ft1.35' class='none'>
    <td class='errorCase'><div class='testcase'>test_shops_list_search: 以商品编号查询商品_retry:1</div></td>
    <td colspan='5' align='center'>

    <!--css div popup start-->
    <a class="popup_link" onfocus='this.blur();' href="javascript:showTestDetail('div_ft1.35')" >
        错误</a>

    <div id='div_ft1.35' class="popup_window">
        <pre>ft1.35: Traceback (most recent call last):
  File "C:\Users\pc\AppData\Local\Programs\Python\Python36\lib\site-packages\selenium\webdriver\common\service.py", line 76, in start
    stdin=PIPE)
  File "C:\Users\pc\AppData\Local\Programs\Python\Python36\lib\subprocess.py", line 709, in __init__
    restore_signals, start_new_session)
  File "C:\Users\pc\AppData\Local\Programs\Python\Python36\lib\subprocess.py", line 997, in _execute_child
    startupinfo)
FileNotFoundError: [WinError 2] 系统找不到指定的文件。

During handling of the above exception, another exception occurred:

Traceback (most recent call last):
  File "G:\Operating_background_test_01\test_case\mytest.py", line 18, in setUp
    self.driver=d.browser_chrome()
  File "G:\Operating_background_test_01\modle\driver.py", line 23, in browser_chrome
    self.driver=webdriver.Chrome(executable_path=os.path.abspath('..')+'\\Application60\\chromedriver.exe')
  File "C:\Users\pc\AppData\Local\Programs\Python\Python36\lib\site-packages\selenium\webdriver\chrome\webdriver.py", line 73, in __init__
    self.service.start()
  File "C:\Users\pc\AppData\Local\Programs\Python\Python36\lib\site-packages\selenium\webdriver\common\service.py", line 83, in start
    os.path.basename(self.path), self.start_error_message)
selenium.common.exceptions.WebDriverException: Message: 'chromedriver.exe' executable needs to be in PATH. Please see https://sites.google.com/a/chromium.org/chromedriver/home

</pre>
    </div>
    <!--css div popup end-->

    </td>
</tr>

<tr id='ft1.36' class='none'>
    <td class='errorCase'><div class='testcase'>test_shops_list_sell_out: 验证商品列表，售罄_retry:1</div></td>
    <td colspan='5' align='center'>

    <!--css div popup start-->
    <a class="popup_link" onfocus='this.blur();' href="javascript:showTestDetail('div_ft1.36')" >
        错误</a>

    <div id='div_ft1.36' class="popup_window">
        <pre>ft1.36: Traceback (most recent call last):
  File "C:\Users\pc\AppData\Local\Programs\Python\Python36\lib\site-packages\selenium\webdriver\common\service.py", line 76, in start
    stdin=PIPE)
  File "C:\Users\pc\AppData\Local\Programs\Python\Python36\lib\subprocess.py", line 709, in __init__
    restore_signals, start_new_session)
  File "C:\Users\pc\AppData\Local\Programs\Python\Python36\lib\subprocess.py", line 997, in _execute_child
    startupinfo)
FileNotFoundError: [WinError 2] 系统找不到指定的文件。

During handling of the above exception, another exception occurred:

Traceback (most recent call last):
  File "G:\Operating_background_test_01\test_case\mytest.py", line 18, in setUp
    self.driver=d.browser_chrome()
  File "G:\Operating_background_test_01\modle\driver.py", line 23, in browser_chrome
    self.driver=webdriver.Chrome(executable_path=os.path.abspath('..')+'\\Application60\\chromedriver.exe')
  File "C:\Users\pc\AppData\Local\Programs\Python\Python36\lib\site-packages\selenium\webdriver\chrome\webdriver.py", line 73, in __init__
    self.service.start()
  File "C:\Users\pc\AppData\Local\Programs\Python\Python36\lib\site-packages\selenium\webdriver\common\service.py", line 83, in start
    os.path.basename(self.path), self.start_error_message)
selenium.common.exceptions.WebDriverException: Message: 'chromedriver.exe' executable needs to be in PATH. Please see https://sites.google.com/a/chromium.org/chromedriver/home

</pre>
    </div>
    <!--css div popup end-->

    </td>
</tr>

    <tr class='errorClass'>
        <td>case_shops.shops_manage</td>
        <td>6</td>
        <td>0</td>
        <td>0</td>
        <td>6</td>
        <td><a href="javascript:showClassDetail('c2',6)">详情</a></td>
    </tr>

<tr id='ft2.1' class='none'>
    <td class='errorCase'><div class='testcase'>test_placeholder_query: 验证商家ID查询_retry:1</div></td>
    <td colspan='5' align='center'>

    <!--css div popup start-->
    <a class="popup_link" onfocus='this.blur();' href="javascript:showTestDetail('div_ft2.1')" >
        错误</a>

    <div id='div_ft2.1' class="popup_window">
        <pre>ft2.1: Traceback (most recent call last):
  File "C:\Users\pc\AppData\Local\Programs\Python\Python36\lib\site-packages\selenium\webdriver\common\service.py", line 76, in start
    stdin=PIPE)
  File "C:\Users\pc\AppData\Local\Programs\Python\Python36\lib\subprocess.py", line 709, in __init__
    restore_signals, start_new_session)
  File "C:\Users\pc\AppData\Local\Programs\Python\Python36\lib\subprocess.py", line 997, in _execute_child
    startupinfo)
FileNotFoundError: [WinError 2] 系统找不到指定的文件。

During handling of the above exception, another exception occurred:

Traceback (most recent call last):
  File "G:\Operating_background_test_01\test_case\mytest.py", line 18, in setUp
    self.driver=d.browser_chrome()
  File "G:\Operating_background_test_01\modle\driver.py", line 23, in browser_chrome
    self.driver=webdriver.Chrome(executable_path=os.path.abspath('..')+'\\Application60\\chromedriver.exe')
  File "C:\Users\pc\AppData\Local\Programs\Python\Python36\lib\site-packages\selenium\webdriver\chrome\webdriver.py", line 73, in __init__
    self.service.start()
  File "C:\Users\pc\AppData\Local\Programs\Python\Python36\lib\site-packages\selenium\webdriver\common\service.py", line 83, in start
    os.path.basename(self.path), self.start_error_message)
selenium.common.exceptions.WebDriverException: Message: 'chromedriver.exe' executable needs to be in PATH. Please see https://sites.google.com/a/chromium.org/chromedriver/home

</pre>
    </div>
    <!--css div popup end-->

    </td>
</tr>

<tr id='ft2.2' class='none'>
    <td class='errorCase'><div class='testcase'>test_shop_ID_query: 验证商家ID查询_retry:1</div></td>
    <td colspan='5' align='center'>

    <!--css div popup start-->
    <a class="popup_link" onfocus='this.blur();' href="javascript:showTestDetail('div_ft2.2')" >
        错误</a>

    <div id='div_ft2.2' class="popup_window">
        <pre>ft2.2: Traceback (most recent call last):
  File "C:\Users\pc\AppData\Local\Programs\Python\Python36\lib\site-packages\selenium\webdriver\common\service.py", line 76, in start
    stdin=PIPE)
  File "C:\Users\pc\AppData\Local\Programs\Python\Python36\lib\subprocess.py", line 709, in __init__
    restore_signals, start_new_session)
  File "C:\Users\pc\AppData\Local\Programs\Python\Python36\lib\subprocess.py", line 997, in _execute_child
    startupinfo)
FileNotFoundError: [WinError 2] 系统找不到指定的文件。

During handling of the above exception, another exception occurred:

Traceback (most recent call last):
  File "G:\Operating_background_test_01\test_case\mytest.py", line 18, in setUp
    self.driver=d.browser_chrome()
  File "G:\Operating_background_test_01\modle\driver.py", line 23, in browser_chrome
    self.driver=webdriver.Chrome(executable_path=os.path.abspath('..')+'\\Application60\\chromedriver.exe')
  File "C:\Users\pc\AppData\Local\Programs\Python\Python36\lib\site-packages\selenium\webdriver\chrome\webdriver.py", line 73, in __init__
    self.service.start()
  File "C:\Users\pc\AppData\Local\Programs\Python\Python36\lib\site-packages\selenium\webdriver\common\service.py", line 83, in start
    os.path.basename(self.path), self.start_error_message)
selenium.common.exceptions.WebDriverException: Message: 'chromedriver.exe' executable needs to be in PATH. Please see https://sites.google.com/a/chromium.org/chromedriver/home

</pre>
    </div>
    <!--css div popup end-->

    </td>
</tr>

<tr id='ft2.3' class='none'>
    <td class='errorCase'><div class='testcase'>test_shops_check_in: 验证商家入驻_retry:1</div></td>
    <td colspan='5' align='center'>

    <!--css div popup start-->
    <a class="popup_link" onfocus='this.blur();' href="javascript:showTestDetail('div_ft2.3')" >
        错误</a>

    <div id='div_ft2.3' class="popup_window">
        <pre>ft2.3: Traceback (most recent call last):
  File "C:\Users\pc\AppData\Local\Programs\Python\Python36\lib\site-packages\selenium\webdriver\common\service.py", line 76, in start
    stdin=PIPE)
  File "C:\Users\pc\AppData\Local\Programs\Python\Python36\lib\subprocess.py", line 709, in __init__
    restore_signals, start_new_session)
  File "C:\Users\pc\AppData\Local\Programs\Python\Python36\lib\subprocess.py", line 997, in _execute_child
    startupinfo)
FileNotFoundError: [WinError 2] 系统找不到指定的文件。

During handling of the above exception, another exception occurred:

Traceback (most recent call last):
  File "G:\Operating_background_test_01\test_case\mytest.py", line 18, in setUp
    self.driver=d.browser_chrome()
  File "G:\Operating_background_test_01\modle\driver.py", line 23, in browser_chrome
    self.driver=webdriver.Chrome(executable_path=os.path.abspath('..')+'\\Application60\\chromedriver.exe')
  File "C:\Users\pc\AppData\Local\Programs\Python\Python36\lib\site-packages\selenium\webdriver\chrome\webdriver.py", line 73, in __init__
    self.service.start()
  File "C:\Users\pc\AppData\Local\Programs\Python\Python36\lib\site-packages\selenium\webdriver\common\service.py", line 83, in start
    os.path.basename(self.path), self.start_error_message)
selenium.common.exceptions.WebDriverException: Message: 'chromedriver.exe' executable needs to be in PATH. Please see https://sites.google.com/a/chromium.org/chromedriver/home

</pre>
    </div>
    <!--css div popup end-->

    </td>
</tr>

<tr id='ft2.4' class='none'>
    <td class='errorCase'><div class='testcase'>test_store_Recharge: 验证商家充值_retry:1</div></td>
    <td colspan='5' align='center'>

    <!--css div popup start-->
    <a class="popup_link" onfocus='this.blur();' href="javascript:showTestDetail('div_ft2.4')" >
        错误</a>

    <div id='div_ft2.4' class="popup_window">
        <pre>ft2.4: Traceback (most recent call last):
  File "C:\Users\pc\AppData\Local\Programs\Python\Python36\lib\site-packages\selenium\webdriver\common\service.py", line 76, in start
    stdin=PIPE)
  File "C:\Users\pc\AppData\Local\Programs\Python\Python36\lib\subprocess.py", line 709, in __init__
    restore_signals, start_new_session)
  File "C:\Users\pc\AppData\Local\Programs\Python\Python36\lib\subprocess.py", line 997, in _execute_child
    startupinfo)
FileNotFoundError: [WinError 2] 系统找不到指定的文件。

During handling of the above exception, another exception occurred:

Traceback (most recent call last):
  File "G:\Operating_background_test_01\test_case\mytest.py", line 18, in setUp
    self.driver=d.browser_chrome()
  File "G:\Operating_background_test_01\modle\driver.py", line 23, in browser_chrome
    self.driver=webdriver.Chrome(executable_path=os.path.abspath('..')+'\\Application60\\chromedriver.exe')
  File "C:\Users\pc\AppData\Local\Programs\Python\Python36\lib\site-packages\selenium\webdriver\chrome\webdriver.py", line 73, in __init__
    self.service.start()
  File "C:\Users\pc\AppData\Local\Programs\Python\Python36\lib\site-packages\selenium\webdriver\common\service.py", line 83, in start
    os.path.basename(self.path), self.start_error_message)
selenium.common.exceptions.WebDriverException: Message: 'chromedriver.exe' executable needs to be in PATH. Please see https://sites.google.com/a/chromium.org/chromedriver/home

</pre>
    </div>
    <!--css div popup end-->

    </td>
</tr>

<tr id='ft2.5' class='none'>
    <td class='errorCase'><div class='testcase'>test_store_grade: 验证商家等级查询_retry:1</div></td>
    <td colspan='5' align='center'>

    <!--css div popup start-->
    <a class="popup_link" onfocus='this.blur();' href="javascript:showTestDetail('div_ft2.5')" >
        错误</a>

    <div id='div_ft2.5' class="popup_window">
        <pre>ft2.5: Traceback (most recent call last):
  File "C:\Users\pc\AppData\Local\Programs\Python\Python36\lib\site-packages\selenium\webdriver\common\service.py", line 76, in start
    stdin=PIPE)
  File "C:\Users\pc\AppData\Local\Programs\Python\Python36\lib\subprocess.py", line 709, in __init__
    restore_signals, start_new_session)
  File "C:\Users\pc\AppData\Local\Programs\Python\Python36\lib\subprocess.py", line 997, in _execute_child
    startupinfo)
FileNotFoundError: [WinError 2] 系统找不到指定的文件。

During handling of the above exception, another exception occurred:

Traceback (most recent call last):
  File "G:\Operating_background_test_01\test_case\mytest.py", line 18, in setUp
    self.driver=d.browser_chrome()
  File "G:\Operating_background_test_01\modle\driver.py", line 23, in browser_chrome
    self.driver=webdriver.Chrome(executable_path=os.path.abspath('..')+'\\Application60\\chromedriver.exe')
  File "C:\Users\pc\AppData\Local\Programs\Python\Python36\lib\site-packages\selenium\webdriver\chrome\webdriver.py", line 73, in __init__
    self.service.start()
  File "C:\Users\pc\AppData\Local\Programs\Python\Python36\lib\site-packages\selenium\webdriver\common\service.py", line 83, in start
    os.path.basename(self.path), self.start_error_message)
selenium.common.exceptions.WebDriverException: Message: 'chromedriver.exe' executable needs to be in PATH. Please see https://sites.google.com/a/chromium.org/chromedriver/home

</pre>
    </div>
    <!--css div popup end-->

    </td>
</tr>

<tr id='ft2.6' class='none'>
    <td class='errorCase'><div class='testcase'>test_store_name: 验证商家名称查询_retry:1</div></td>
    <td colspan='5' align='center'>

    <!--css div popup start-->
    <a class="popup_link" onfocus='this.blur();' href="javascript:showTestDetail('div_ft2.6')" >
        错误</a>

    <div id='div_ft2.6' class="popup_window">
        <pre>ft2.6: Traceback (most recent call last):
  File "C:\Users\pc\AppData\Local\Programs\Python\Python36\lib\site-packages\selenium\webdriver\common\service.py", line 76, in start
    stdin=PIPE)
  File "C:\Users\pc\AppData\Local\Programs\Python\Python36\lib\subprocess.py", line 709, in __init__
    restore_signals, start_new_session)
  File "C:\Users\pc\AppData\Local\Programs\Python\Python36\lib\subprocess.py", line 997, in _execute_child
    startupinfo)
FileNotFoundError: [WinError 2] 系统找不到指定的文件。

During handling of the above exception, another exception occurred:

Traceback (most recent call last):
  File "G:\Operating_background_test_01\test_case\mytest.py", line 18, in setUp
    self.driver=d.browser_chrome()
  File "G:\Operating_background_test_01\modle\driver.py", line 23, in browser_chrome
    self.driver=webdriver.Chrome(executable_path=os.path.abspath('..')+'\\Application60\\chromedriver.exe')
  File "C:\Users\pc\AppData\Local\Programs\Python\Python36\lib\site-packages\selenium\webdriver\chrome\webdriver.py", line 73, in __init__
    self.service.start()
  File "C:\Users\pc\AppData\Local\Programs\Python\Python36\lib\site-packages\selenium\webdriver\common\service.py", line 83, in start
    os.path.basename(self.path), self.start_error_message)
selenium.common.exceptions.WebDriverException: Message: 'chromedriver.exe' executable needs to be in PATH. Please see https://sites.google.com/a/chromium.org/chromedriver/home

</pre>
    </div>
    <!--css div popup end-->

    </td>
</tr>

        <tr id='total_row'>
            <td>总计</td>
            <td>42</td>
            <td>0</td>
            <td>0</td>
            <td>42</td>
            <td>&nbsp;</td>
        </tr>
    </table>

        <div id='ending'>&nbsp;</div>
        
    <script type="text/javascript">
        // 基于准备好的dom，初始化echarts实例
        var myChart = echarts.init(document.getElementById('chart'));

        // 指定图表的配置项和数据
        var option = {
            title : {
                text: '测试执行情况',
                x:'center'
            },
            tooltip : {
                trigger: 'item',
                formatter: "{a} <br/>{b} : {c} ({d}%)"
            },
            color: ['#95b75d', 'grey', '#b64645'],
            legend: {
                orient: 'vertical',
                left: 'left',
                data: ['通过','失败','错误']
            },
            series : [
                {
                    name: '测试执行情况',
                    type: 'pie',
                    radius : '60%',
                    center: ['50%', '60%'],
                    data:[
                        {value:0, name:'通过'},
                        {value:0, name:'失败'},
                        {value:42, name:'错误'}
                    ],
                    labelLine:
                        {
                            show: false,
                            lineStyle:{
                                color:'transparent'
                            },
                        },
                    label:
                        {
                            formatter:(d) => {
                            return ''
                        }
                    },
                    itemStyle: {
                        emphasis: {
                            shadowBlur: 10,
                            shadowOffsetX: 0,
                            shadowColor: 'rgba(0, 0, 0, 0.5)'
                        }
                    }
                }
            ]
        };

        // 使用刚指定的配置项和数据显示图表。
        myChart.setOption(option);
    </script>
    
    </div>
</body>
</html>
